<robot name="rover">
<link name="base_footprint">
<inertial>
<origin xyz="0 0 0" rpy="0 0 0"/>
<mass value="0" />
<inertia ixx="0" ixy="0"  ixz="0" iyy="0" iyz="0" izz="0" />
</inertial>
</link>

<link name="base_link">
<visual>
<origin xyz="-2.798540501062457092e-17 6.1093673644573049834e-18 0" rpy="0 -5.1977048828224496093e-113 0" />
<geometry>
<mesh filename="package://rover_description/urdf/rover/base_link.stl"/>
</geometry>
<material name="base_link_material">
<color rgba="0.61568627450980395466 0.81176470588235294379 0.92941176470588238168 1.0"/>
</material>
</visual>
<collision>
<origin xyz="-2.798540501062457092e-17 6.1093673644573049834e-18 0" rpy="0 -5.1977048828224496093e-113 0" />
<geometry>
<mesh filename="package://rover_description/urdf/rover/base_link.stl"/>
</geometry>
</collision>
<inertial>
<origin xyz="-5.5267729493257816212e-18 6.3769590725128424662e-18 0.19001085791228139454" rpy="0 0 0"/>
<mass value="40" />
<inertia ixx="1.0833233794146899243" ixy="-1.8675004218029757146e-16"  ixz="5.630795218859451012e-113" iyy="1.8679041881453550822" iyz="-9.7067160610783111063e-129" izz="1.9886593553962703673" />
</inertial>
</link>

<link name="rr_steering_link">
<visual>
<origin xyz="0 -0.099999999999999977796 -0.23000000000000000999" rpy="0 -0 -3.5371013739549831335e-45" />
<geometry>
<mesh filename="package://rover_description/urdf/rover/steering_link.stl"/>
</geometry>
<material name="steering_link_material">
<color rgba="0.61568627450980395466 0.81176470588235294379 0.92941176470588238168 1.0"/>
</material>
</visual>
<collision>
<origin xyz="0 -0.099999999999999977796 -0.23000000000000000999" rpy="0 -0 -3.5371013739549831335e-45" />
<geometry>
<mesh filename="package://rover_description/urdf/rover/steering_link.stl"/>
</geometry>
</collision>
<inertial>
<origin xyz="2.5048502339963977633e-18 -0.088691628255863019792 -0.10069461572907584257" rpy="0 0 0"/>
<mass value="0.99999999999999988898" />
<inertia ixx="0.0061121872660202690095" ixy="-3.5428631502324024239e-45"  ixz="5.4011044810356159022e-46" iyy="0.0059423770522869772542" iyz="-0.00091147906360536856338" izz="0.0018215670507348868425" />
</inertial>
</link>

<link name="rr_wheel_link">
<visual>
<origin xyz="0 0 0" rpy="1.570796326794896558 1.570796326794896558 0" />
<geometry>
<mesh filename="package://rover_description/urdf/rover/wheel.stl"/>
</geometry>
<material name="wheel_material">
<color rgba="0.61568627450980395466 0.81176470588235294379 0.92941176470588238168 1.0"/>
</material>
</visual>
<collision>
<origin xyz="0 0 0" rpy="1.570796326794896558 1.570796326794896558 0" />
<geometry>
<mesh filename="package://rover_description/urdf/rover/wheel.stl"/>
</geometry>
</collision>
<inertial>
<origin xyz="-1.8236700169436135526e-53 -1.0310768331388757477e-17 -3.6470232831486701118e-62" rpy="0 0 0"/>
<mass value="2" />
<inertia ixx="0.0091811666666666656017" ixy="0"  ixz="0" iyy="0.0091811666666666690712" iyz="9.6492095521497396071e-45" izz="0.01622900000000000037" />
</inertial>
</link>

<joint name="rr_wheel_joint" type="continuous">
<origin xyz="-1.1102230246251565404e-16 -0.014999999999999985567 -0.16000000000000000333" rpy="1.570796326794896558 1.570796326794896558 0" />
<parent link="rr_steering_link" />
<child link="rr_wheel_link" />
<axis xyz="0 0 1"/>
<limit effort="1.5" velocity="22" />
<joint_properties friction="0.0"/>
</joint>

<joint name="rr_steering_joint" type="revolute">
<origin xyz="-0.29750000000000176303 -0.18249999999999486078 0" rpy="2.7341918974960333747e-27 3.8285686989646017659e-16 -3.1415926535897691352" />
<parent link="base_link" />
<child link="rr_steering_link" />
<axis xyz="0 0 1"/>
<limit effort="1.5" velocity="22" lower="-3.141592653589793116" upper="3.141592653589793116"/>
<joint_properties friction="0.0"/>
</joint>

<link name="rl_steering_link">
<visual>
<origin xyz="0 -0.099999999999999991673 -0.23000000000000000999" rpy="0 -0 -6.4520195853714940548e-45" />
<geometry>
<mesh filename="package://rover_description/urdf/rover/steering_link.stl"/>
</geometry>
<material name="steering_link_material">
<color rgba="0.61568627450980395466 0.81176470588235294379 0.92941176470588238168 1.0"/>
</material>
</visual>
<collision>
<origin xyz="0 -0.099999999999999991673 -0.23000000000000000999" rpy="0 -0 -6.4520195853714940548e-45" />
<geometry>
<mesh filename="package://rover_description/urdf/rover/steering_link.stl"/>
</geometry>
</collision>
<inertial>
<origin xyz="2.5048502339963977633e-18 -0.08869162825586303367 -0.10069461572907584257" rpy="0 0 0"/>
<mass value="0.99999999999999988898" />
<inertia ixx="0.0061121872660202690095" ixy="-4.7249230382039756353e-45"  ixz="7.1868939724556140696e-46" iyy="0.0059423770522869772542" iyz="-0.00091147906360536856338" izz="0.0018215670507348868425" />
</inertial>
</link>

<link name="rl_wheel_link">
<visual>
<origin xyz="0 0 0" rpy="1.570796326794896558 1.570796326794896558 0" />
<geometry>
<mesh filename="package://rover_description/urdf/rover/wheel.stl"/>
</geometry>
<material name="wheel_material">
<color rgba="0.61568627450980395466 0.81176470588235294379 0.92941176470588238168 1.0"/>
</material>
</visual>
<collision>
<origin xyz="0 0 0" rpy="1.570796326794896558 1.570796326794896558 0" />
<geometry>
<mesh filename="package://rover_description/urdf/rover/wheel.stl"/>
</geometry>
</collision>
<inertial>
<origin xyz="-1.8236700169436135526e-53 -1.0310768331388757477e-17 1.176635466657525221e-97" rpy="0 0 0"/>
<mass value="2" />
<inertia ixx="0.0091811666666666656017" ixy="0"  ixz="-1.2855592675981450913e-44" iyy="0.0091811666666666690712" iyz="0" izz="0.01622900000000000037" />
</inertial>
</link>

<joint name="rl_wheel_joint" type="continuous">
<origin xyz="-5.5511151231257827021e-17 -0.015000000000000013323 -0.16000000000000000333" rpy="-1.570796326794896558 2.5243548967072377773e-29 -6.4520195853711717026e-45" />
<parent link="rl_steering_link" />
<child link="rl_wheel_link" />
<axis xyz="0 0 1"/>
<limit effort="1.5" velocity="22" />
<joint_properties friction="0.0"/>
</joint>

<joint name="rl_steering_joint" type="revolute">
<origin xyz="-0.2975000000000000977 0.18250000000000013434 0" rpy="-2.7468136719795358428e-27 -5.0532154981114325992e-16 1.6829674908629561938e-14" />
<parent link="base_link" />
<child link="rl_steering_link" />
<axis xyz="0 0 1"/>
<limit effort="1.5" velocity="22" lower="-3.141592653589793116" upper="3.141592653589793116"/>
<joint_properties friction="0.0"/>
</joint>

<link name="fr_steering_link">
<visual>
<origin xyz="5.5511151231257827021e-17 -0.10000000000000000555 -0.23000000000000000999" rpy="0 -0 0" />
<geometry>
<mesh filename="package://rover_description/urdf/rover/steering_link.stl"/>
</geometry>
<material name="steering_link_material">
<color rgba="0.61568627450980395466 0.81176470588235294379 0.92941176470588238168 1.0"/>
</material>
</visual>
<collision>
<origin xyz="5.5511151231257827021e-17 -0.10000000000000000555 -0.23000000000000000999" rpy="0 -0 0" />
<geometry>
<mesh filename="package://rover_description/urdf/rover/steering_link.stl"/>
</geometry>
</collision>
<inertial>
<origin xyz="5.8016001465254228636e-17 -0.088691628255863047547 -0.10069461572907584257" rpy="0 0 0"/>
<mass value="0.99999999999999988898" />
<inertia ixx="0.0061121872660202690095" ixy="0"  ixz="0" iyy="0.0059423770522869772542" iyz="-0.00091147906360536856338" izz="0.0018215670507348868425" />
</inertial>
</link>

<link name="fr_wheel_link">
<visual>
<origin xyz="0 0 0" rpy="1.570796326794896558 1.570796326794896558 0" />
<geometry>
<mesh filename="package://rover_description/urdf/rover/wheel.stl"/>
</geometry>
<material name="wheel_material">
<color rgba="0.61568627450980395466 0.81176470588235294379 0.92941176470588238168 1.0"/>
</material>
</visual>
<collision>
<origin xyz="0 0 0" rpy="1.570796326794896558 1.570796326794896558 0" />
<geometry>
<mesh filename="package://rover_description/urdf/rover/wheel.stl"/>
</geometry>
</collision>
<inertial>
<origin xyz="-1.8236700169436135526e-53 -1.0310768331388757477e-17 -3.3108659528003041048e-75" rpy="0 0 0"/>
<mass value="2" />
<inertia ixx="0.0091811666666666656017" ixy="0"  ixz="0" iyy="0.0091811666666666690712" iyz="1.280242363083174067e-32" izz="0.01622900000000000037" />
</inertial>
</link>

<joint name="fr_wheel_joint" type="continuous">
<origin xyz="5.5511151231257827021e-17 -0.014999999999999985567 -0.16000000000000000333" rpy="1.570796326794896558 1.570796326794896558 0" />
<parent link="fr_steering_link" />
<child link="fr_wheel_link" />
<axis xyz="0 0 1"/>
<limit effort="1.5" velocity="22" />
<joint_properties friction="0.0"/>
</joint>

<joint name="fr_steering_joint" type="revolute">
<origin xyz="0.29749999999999998668 -0.18250000000000007883 0" rpy="1.1864468014523915315e-27 3.5032461608120426773e-46 -3.141592653589793116" />
<parent link="base_link" />
<child link="fr_steering_link" />
<axis xyz="0 0 1"/>
<limit effort="1.5" velocity="22" lower="-3.141592653589793116" upper="3.141592653589793116"/>
<joint_properties friction="0.0"/>
</joint>

<link name="fl_steering_link">
<visual>
<origin xyz="0 -0.10000000000000000555 -0.23000000000000000999" rpy="0 -0 2.7904965608089986245e-104" />
<geometry>
<mesh filename="package://rover_description/urdf/rover/steering_link.stl"/>
</geometry>
<material name="steering_link_material">
<color rgba="0.61568627450980395466 0.81176470588235294379 0.92941176470588238168 1.0"/>
</material>
</visual>
<collision>
<origin xyz="0 -0.10000000000000000555 -0.23000000000000000999" rpy="0 -0 2.7904965608089986245e-104" />
<geometry>
<mesh filename="package://rover_description/urdf/rover/steering_link.stl"/>
</geometry>
</collision>
<inertial>
<origin xyz="2.5048502339963977633e-18 -0.088691628255863047547 -0.10069461572907584257" rpy="0 0 0"/>
<mass value="0.99999999999999988898" />
<inertia ixx="0.0061121872660202690095" ixy="4.7385481741334085412e-108"  ixz="2.5434791922401337913e-107" iyy="0.0059423770522869772542" iyz="-0.00091147906360536856338" izz="0.0018215670507348868425" />
</inertial>
</link>

<link name="fl_wheel_link">
<visual>
<origin xyz="0 -2.7755575615628913511e-17 0" rpy="1.570796326794896558 1.570796326794896558 0" />
<geometry>
<mesh filename="package://rover_description/urdf/rover/wheel.stl"/>
</geometry>
<material name="wheel_material">
<color rgba="0.61568627450980395466 0.81176470588235294379 0.92941176470588238168 1.0"/>
</material>
</visual>
<collision>
<origin xyz="0 -2.7755575615628913511e-17 0" rpy="1.570796326794896558 1.570796326794896558 0" />
<geometry>
<mesh filename="package://rover_description/urdf/rover/wheel.stl"/>
</geometry>
</collision>
<inertial>
<origin xyz="-1.8236700169436135526e-53 -3.8066343947017672528e-17 -2.212099860970205564e-86" rpy="0 0 0"/>
<mass value="2" />
<inertia ixx="0.0091811666666666656017" ixy="0"  ixz="3.0822366781446657224e-35" iyy="0.0091811666666666690712" iyz="0" izz="0.01622900000000000037" />
</inertial>
</link>

<joint name="fl_wheel_joint" type="continuous">
<origin xyz="0 -0.015000000000000041078 -0.16000000000000000333" rpy="-1.570796326794896558 -5.5511151231257925629e-17 -5.1336471294911238066e-17" />
<parent link="fl_steering_link" />
<child link="fl_wheel_link" />
<axis xyz="0 0 1"/>
<limit effort="1.5" velocity="22" />
<joint_properties friction="0.0"/>
</joint>

<joint name="fl_steering_joint" type="revolute">
<origin xyz="0.29749999999999993117 0.18250000000000002331 0" rpy="-1.1864468014524126967e-27 1.0593816390296488477e-42 8.8817841970015442019e-16" />
<parent link="base_link" />
<child link="fl_steering_link" />
<axis xyz="0 0 1"/>
<limit effort="1.5" velocity="22" lower="-3.141592653589793116" upper="3.141592653589793116"/>
<joint_properties friction="0.0"/>
</joint>

<link name="lidar_link">
<visual>
<origin xyz="0 -2.2962127484012875716e-18 -0.029000000000000025757" rpy="0 -0 0" />
<geometry>
<mesh filename="package://rover_description/urdf/rover/lidar_link.stl"/>
</geometry>
<material name="lidar_link_material">
<color rgba="0.61568627450980395466 0.81176470588235294379 0.92941176470588238168 1.0"/>
</material>
</visual>
<collision>
<origin xyz="0 -2.2962127484012875716e-18 -0.029000000000000025757" rpy="0 -0 0" />
<geometry>
<mesh filename="package://rover_description/urdf/rover/lidar_link.stl"/>
</geometry>
</collision>
<inertial>
<origin xyz="8.0292509306519218601e-19 3.8518598887744717061e-34 0.003499999999999975353" rpy="0 0 0"/>
<mass value="0.30209358607378605788" />
<inertia ixx="0.0002125668931175443005" ixy="2.7664970832468516446e-129"  ixz="0" iyy="0.0002125668931175443276" iyz="0" izz="0.00021240955270813093687" />
</inertial>
</link>

<joint name="lidar_joint" type="fixed">
<origin xyz="0.12249999999999997002 6.1093673644576578138e-18 0.40899999999999997469" rpy="-9.5925486074876183482e-28 5.5637880468010420896e-97 4.6894542932646612788e-70" />
<parent link="base_link" />
<child link="lidar_link" />
<axis xyz="0 0 1"/>
<limit effort="1.5" velocity="22" />
<joint_properties friction="0.0"/>
</joint>

<link name="imu_link">
<inertial>
<origin xyz="0 0 0" rpy="0 0 0"/>
<mass value="0" />
<inertia ixx="0" ixy="0"  ixz="0" iyy="0" iyz="0" izz="0" />
</inertial>
</link>

<joint name="imu_joint" type="fixed">
<origin xyz="0.12249999999999997002 6.1093673644576593545e-18 0.40899999999999997469" rpy="-5.5511151232446270627e-17 8.9923910584377721832e-16 -2.7117093616972959565e-31" />
<parent link="base_link" />
<child link="imu_link" />
<axis xyz="0 0 1"/>
<limit effort="1.5" velocity="22" />
<joint_properties friction="0.0"/>
</joint>

<link name="gps_link">
<inertial>
<origin xyz="0 0 0" rpy="0 0 0"/>
<mass value="0" />
<inertia ixx="0" ixy="0"  ixz="0" iyy="0" iyz="0" izz="0" />
</inertial>
</link>

<joint name="gps_joint" type="fixed">
<origin xyz="0.12249999999999997002 6.1093673644576608953e-18 0.40899999999999997469" rpy="-5.5511151232457807718e-17 8.9923910584377721832e-16 -2.4651903288156579508e-31" />
<parent link="base_link" />
<child link="gps_link" />
<axis xyz="0 0 1"/>
<limit effort="1.5" velocity="22" />
<joint_properties friction="0.0"/>
</joint>

<link name="camera_link">
<visual>
<origin xyz="-0.010000000000000008882 0 -2.3322217863181845357e-17" rpy="-1.570796326794896558 1.570796326794896558 0" />
<geometry>
<mesh filename="package://rover_description/urdf/rover/camera_link.stl"/>
</geometry>
<material name="camera_link_material">
<color rgba="0.61568627450980395466 0.81176470588235294379 0.92941176470588238168 1.0"/>
</material>
</visual>
<collision>
<origin xyz="-0.010000000000000008882 0 -2.3322217863181845357e-17" rpy="-1.570796326794896558 1.570796326794896558 0" />
<geometry>
<mesh filename="package://rover_description/urdf/rover/camera_link.stl"/>
</geometry>
</collision>
<inertial>
<origin xyz="-0.010293814432989699739 5.5548728130610748964e-18 -2.0678055447695336036e-17" rpy="0 0 0"/>
<mass value="0.061226400000000021084" />
<inertia ixx="5.5992700000000003482e-05" ixy="0"  ixz="3.0245200390706104662e-21" iyy="5.3249479313402056538e-05" iyz="0" izz="6.5985393134020647296e-06" />
</inertial>
</link>

<joint name="camera_joint" type="fixed">
<origin xyz="0.34249999999999997113 6.1093673644585314156e-18 0.38000000000000005995" rpy="-1.570796326794896558 -6.1232339957370680217e-17 -6.1232339957366809868e-17" />
<parent link="base_link" />
<child link="camera_link" />
<axis xyz="0 0 1"/>
<limit effort="1.5" velocity="22" />
<joint_properties friction="0.0"/>
</joint>

<joint name="base_link_joint" type="fixed">
<origin xyz="-6.1629758220391547298e-33 -3.5360073778949650262e-31 0.28699999999999997735" rpy="1.1864468014523915315e-27 -0 -2.1680136497538192772e-70" />
<parent link="base_footprint" />
<child link="base_link" />
<axis xyz="0 0 1"/>
<limit effort="1.5" velocity="22" />
<joint_properties friction="0.0"/>
</joint>

<ros2_control name="GazeboSystem" type="system">
<hardware>
    <plugin>gazebo_ros2_control/GazeboSystem</plugin>
</hardware>

<joint name="fl_wheel_joint">
    <command_interface name="velocity">
    <param name="min">-3.14</param>
    <param name="max">3.14</param>
    </command_interface>
    <state_interface name="velocity"/>
    <state_interface name="effort"/>
</joint>

<joint name="fr_wheel_joint">
    <command_interface name="velocity">
    <param name="min">-3.14</param>
    <param name="max">3.14</param>
    </command_interface>
    <state_interface name="velocity"/>
    <state_interface name="effort"/>
</joint>

<joint name="rl_wheel_joint">
    <command_interface name="velocity">
    <param name="min">-3.14</param>
    <param name="max">3.14</param>
    </command_interface>
    <state_interface name="velocity"/>
    <state_interface name="effort"/>
</joint>

<joint name="rr_wheel_joint">
    <command_interface name="velocity">
    <param name="min">-3.14</param>
    <param name="max">3.14</param>
    </command_interface>
    <state_interface name="velocity"/>
    <state_interface name="effort"/>
</joint>

<joint name="fl_steering_joint">
    <command_interface name="position">
    <param name="min">-3.14</param>
    <param name="max">3.14</param>
    </command_interface>
    <state_interface name="position"/>
    <state_interface name="effort"/>
</joint>

<joint name="fr_steering_joint">
    <command_interface name="position">
    <param name="min">-3.14</param>
    <param name="max">3.14</param>
    </command_interface>
    <state_interface name="position"/>
    <state_interface name="effort"/>
</joint>

<joint name="rl_steering_joint">
    <command_interface name="position">
    <param name="min">-3.14</param>
    <param name="max">3.14</param>
    </command_interface>
    <state_interface name="position"/>
    <state_interface name="effort"/>
</joint>

<joint name="rr_steering_joint">
    <command_interface name="position">
    <param name="min">-3.14</param>
    <param name="max">3.14</param>
    </command_interface>
    <state_interface name="position"/>
    <state_interface name="effort"/>
</joint>
</ros2_control>

<gazebo>
<plugin name="four_ws_robot_joint_state" filename="libgazebo_ros_joint_state_publisher.so">
    <ros>
    <remapping>~/out:=joint_states</remapping>
    </ros>
    <update_rate>30</update_rate>
    <joint_name>fl_wheel_joint</joint_name>
    <joint_name>fr_wheel_joint</joint_name>
    <joint_name>rl_wheel_joint</joint_name>
    <joint_name>rr_wheel_joint</joint_name>
    <joint_name>fl_steering_joint</joint_name>
    <joint_name>fr_steering_joint</joint_name>
    <joint_name>rl_steering_joint</joint_name>
    <joint_name>rr_steering_joint</joint_name>
</plugin>

<plugin name="gazebo_ros2_control" filename="libgazebo_ros2_control.so">
    <parameters>/home/station/ros2_ws/install/rover_description/share/rover_description/config/controllers.yaml</parameters>
</plugin>
</gazebo>

<gazebo reference="lidar_link">
<sensor name="lidar" type="ray">
    <pose>0 0 0 0 0 0</pose>
    <always_on>true</always_on>
    <visualize>false</visualize>
    <update_rate>10</update_rate>
    <ray>
    <scan>
        <horizontal>
        <samples>360</samples>
        <resolution>1.00000</resolution>
        <min_angle>0.000000</min_angle>
        <max_angle>6.280000</max_angle>
        </horizontal>
        <vertical>
        <samples>90</samples>
        <resolution>1.00000</resolution>
        <min_angle>0.0</min_angle>
        <max_angle>1.5708</max_angle>
        </vertical>
    </scan>
    <range>
        <min>0.10</min>
        <max>30.00</max>
        <resolution>0.015000</resolution>
    </range>
    <noise>
        <type>gaussian</type>
        <mean>0.0</mean>
        <stddev>0.01</stddev>
    </noise>
    </ray>
    <plugin name="scan" filename="libgazebo_ros_ray_sensor.so">
    <ros>
        <namespace>rover</namespace>
        <remapping>~/out:=unitree/lidar_points</remapping>
    </ros>
    <output_type>sensor_msgs/PointCloud2</output_type>
    <frame_name>lidar_link</frame_name>
    </plugin>
</sensor>
</gazebo>
<gazebo reference="imu_link">
<sensor name="imu_sensor" type="imu">
    <pose>0 0 0 0 0 0</pose>
    <always_on>true</always_on>
    <update_rate>10.0</update_rate>

    <imu>
    <angular_velocity>
        <noise>
        <type>gaussian</type>
        <mean>0.0</mean>
        <stddev>0.01</stddev>
        </noise>
    </angular_velocity>

    <linear_acceleration>
        <noise>
        <type>gaussian</type>
        <mean>0.0</mean>
        <stddev>0.01</stddev>
        </noise>
    </linear_acceleration>

    <orientation>
        <noise>
        <type>gaussian</type>
        <mean>0.0</mean>
        <stddev>0.001</stddev>
        </noise>
    </orientation>
    </imu>

    <plugin name="imu_sensor_plugin" filename="libgazebo_ros_imu_sensor.so">
    <ros>
        <namespace>rover</namespace>
        <remapping>~/out:=unitree/imu</remapping>
    </ros>
    <frame_name>imu_link</frame_name>
    </plugin>
</sensor>
</gazebo>
<gazebo reference="gps_link">
<sensor name="gps_sensor" type="gps">
    <pose>0 0 0 0 0 0</pose>
    <always_on>true</always_on>
    <update_rate>10.0</update_rate>

    <plugin name="gps_sensor_plugin" filename="libgazebo_ros_gps_sensor.so">
    <ros>
        <namespace>rover</namespace>
        <remapping>~/out:=gps/rawdata</remapping>
    </ros>
    <frame_name>gps_link</frame_name>
    </plugin>
</sensor>
</gazebo>
<gazebo reference="camera_link">
    <sensor name="depth_camera" type="depth">
        <pose>0 0 0 0 0 0</pose>
        <always_on>true</always_on>
        <update_rate>30</update_rate>
        <camera>
            <horizontal_fov>1.047</horizontal_fov>
            <image>
            <width>640</width>
            <height>480</height>
            <format>R8G8B8</format>
            </image>
            <clip>
            <near>0.4</near>
            <far>10</far>
            </clip>
        </camera>
        <plugin name="gazebo_ros_camera" filename="libgazebo_ros_camera.so">
            <ros>
                <namespace>rover</namespace>
            </ros>
            <camera_name>camera</camera_name>
            <frame_name>camera_frame</frame_name>

            <image_topic>camera/color/image_raw</image_topic>
            <camera_info_topic>camera/color/camera_info</camera_info_topic>
            
            <depth_image>true</depth_image>
            <depth_image_topic>camera/depth/image_raw</depth_image_topic>
            <depth_camera_info_topic>camera/depth/camera_info</depth_camera_info_topic>
            
            <point_cloud>true</point_cloud>
            <point_cloud_topic>camera/depth/points</point_cloud_topic>
        </plugin>
    </sensor>
</gazebo>


<link name="camera_frame">
    <inertial>
    <origin xyz="0 0 0" rpy="0 0 0"/>
    <mass value="0" />
    <inertia ixx="0" ixy="0"  ixz="0" iyy="0" iyz="0" izz="0" />
    </inertial>
</link>
<joint name="camera_frame_joint" type="fixed">
    <origin xyz="0 0 0" rpy="1.5708 3.1416 1.5708" />
    <parent link="camera_link" />
    <child link="camera_frame" />
    <axis xyz="0 0 1"/>
    <limit effort="1.5" velocity="22" />
    <joint_properties friction="0.0"/>
</joint>
<link name="camera_color_frame">
    <inertial>
    <origin xyz="0 0 0" rpy="0 0 0"/>
    <mass value="0" />
    <inertia ixx="0" ixy="0"  ixz="0" iyy="0" iyz="0" izz="0" />
    </inertial>
</link>
<joint name="camera_color_frame_joint" type="fixed">
    <origin xyz="0 0 0" rpy="0 0 0" />
    <parent link="camera_link" />
    <child link="camera_color_frame" />
    <axis xyz="0 0 1"/>
    <limit effort="1.5" velocity="22" />
    <joint_properties friction="0.0"/>
</joint>
<link name="camera_color_optical_frame">
    <inertial>
    <origin xyz="0 0 0" rpy="0 0 0"/>
    <mass value="0" />
    <inertia ixx="0" ixy="0"  ixz="0" iyy="0" iyz="0" izz="0" />
    </inertial>
</link>
<joint name="camera_color_optical_frame_joint" type="fixed">
    <origin xyz="0 0 0" rpy="0 0 0" />
    <parent link="camera_link" />
    <child link="camera_color_optical_frame" />
    <axis xyz="0 0 1"/>
    <limit effort="1.5" velocity="22" />
    <joint_properties friction="0.0"/>
</joint>
<link name="camera_depth_frame">
    <inertial>
    <origin xyz="0 0 0" rpy="0 0 0"/>
    <mass value="0" />
    <inertia ixx="0" ixy="0"  ixz="0" iyy="0" iyz="0" izz="0" />
    </inertial>
</link>
<joint name="camera_depth_frame_joint" type="fixed">
    <origin xyz="0 0 0" rpy="0 0 0" />
    <parent link="camera_link" />
    <child link="camera_depth_frame" />
    <axis xyz="0 0 1"/>
    <limit effort="1.5" velocity="22" />
    <joint_properties friction="0.0"/>
</joint>
<link name="camera_depth_optical_frame">
    <inertial>
    <origin xyz="0 0 0" rpy="0 0 0"/>
    <mass value="0" />
    <inertia ixx="0" ixy="0"  ixz="0" iyy="0" iyz="0" izz="0" />
    </inertial>
</link>
<joint name="camera_depth_optical_frame_joint" type="fixed">
    <origin xyz="0 0 0" rpy="0 0 0" />
    <parent link="camera_link" />
    <child link="camera_depth_optical_frame" />
    <axis xyz="0 0 1"/>
    <limit effort="1.5" velocity="22" />
    <joint_properties friction="0.0"/>
</joint>
</robot>
